Workbook
Name \0: #REF!
Name \A: #REF!
Name \asdf: #REF!
Name \B: #REF!
Name \C: #REF!
Name \d: #REF!
Name \E: #REF!
Name \F: #REF!
Name \Fa: #REF!
Name \G: #REF!
Name \H: #REF!
Name \I: #REF!
Name \K: #REF!
Name \l: #REF!
Name \M: #REF!
Name \n: #REF!
Name \P: #REF!
Name \Q: #REF!
Name \R: #REF!
Name \S: #REF!
Name \T: #REF!
Name \U: #REF!
Name \V: #REF!
Name \W: #REF!
Name \X: #REF!
Name \Y: #REF!
Name \Z: #REF!
Name _: #REF!
Name __________cmp1: #REF!
Name __________glf1: #REF!
Name __________hrh1: #REF!
Name __________hrm1: #REF!
Name __________kit61: #REF!
Name __________lbh1: #REF!
Name __________lbm1: #REF!
Name __________pkh1: #REF!
Name __________pkm1: #REF!
Name __________rsh1: #REF!
Name __________rsm1: #REF!
Name __________rst1: #REF!
Name __________rst2: #REF!
Name __________rst3: #REF!
Name __________rst4: #REF!
Name __________rt1: #REF!
Name __________rt2: #REF!
Name __________rt3: #REF!
Name __________rt4: #REF!
Name __________rtm4: #REF!
Name __________sph1: #REF!
Name __________spm1: #REF!
Name __________tnh1: #REF!
Name __________tnm1: #REF!
Name _________key1: #REF!
Name _________key2: #REF!
Name ________agc2: #REF!
Name ________agc3: #REF!
Name ________jo2: {#N/A,#N/A,FALSE,"DCF-COM";#N/A,#N/A,FALSE,"VAC-COM"}
Name ________jo3: {"CASHFLOW",#N/A,FALSE,"Northpointe"}
Name ________jo4: {#N/A,#N/A,FALSE,"SHEET1";#N/A,#N/A,FALSE,"SHEET2";#N/A,#N/A,FALSE,"SHEET3";#N/A,#N/A,FALSE,"SHEET4"}
Name ________key1: #REF!

Sheet llm_README
A1: llm_README - Workbook Documentation
A3: WORKBOOK SUMMARY
A4: Business Purpose: | B4: Construction/Real Estate project budget management system. Tracks job setup, forecasts, budgets, vendor details, tenant estimates, and payment applications. Contains logging mechanisms for budget changes and error tracking.
A6: Metrics:
A7: - Total Sheets: | B7: 11 (excluding llm_README)
A8: - Visible Sheets: | B8: 11
A9: - Hidden Sheets: | B9: 0
A10: - Generation Mode: | B10: standard
A11: - Generated: | B11: 2025-08-03T04:47:55.965Z
A13: SHEET DETAILS
A15: Sheet: 00_JobSetup
A16: - Dimensions: | B16: 37 rows x 18 columns
A17: - Used Range: | B17: B2:D31
A18: - Headers: | B18: Row 7: Vendor (B7), Category (C7), Forecasted Cost Type (D7)
A20: Sheet: 01_ForecastLog
A21: - Dimensions: | B21: 66 rows x 6 columns
A22: - Used Range: | B22: B2:S38
A24: ═══════════════════════════════════════════
A25: DETAILED SHEET ANALYSIS
A26: ═══════════════════════════════════════════
A28: 1. 00_JobSetup (Type: Setup)
A29: Dimensions: | C29: 37 rows × 18 columns
A30: Used Range: | C30: A1:D31
A31: Purpose: | C31: Initial job configuration with property details and vendor assignments
A32: Headers Found: | C32: A7:, B7:Vendor, C7:Category, D7:Forecasted Cost Type
A34: 2. 01_ForecastLog (Type: Log)
A35: Dimensions: | C35: 66 rows × 6 columns
A36: Used Range: | C36: A1:S38
A37: Purpose: | C37: Tracks forecast changes and budget modifications over time
A38: Headers Found: | C38: A7:, B7:Category, C7:Budget Type, D7:Budget Amount, E7:Budget Status, F7:Date Entered, G7:Budget Notes, H7:, I7:, J7:, K7:, L7:, M7:, N7:, O7:, P7:, Q7:, R7:, S7:
A40: 3. 02_BudgetLog (Type: Log)
A41: Dimensions: | C41: 62 rows × 12 columns
A42: Used Range: | C42: A1:G67
A43: 4-10. Additional Sheets Summary: | C43: Detailed budget tracking log with categories and amounts
A44: • 03_BudgetReport: | C44: A7:, B7:Category, C7:Original Budget, D7:Approved Changes, E7:Revised Budget, F7:Revised Budget PSF, G7:Committed Cost | D44: Consolidated budget reporting with actuals vs forecasts
A45: • 04_VendorDetail: | D45: Vendor information and contract details
A46: • zz_data: | D46: Master data table with property and vendor information
A47: • ErrorLog: | D47: System error tracking and debugging log
A48: • zzz_yardi import: | D48: Yardi system data import staging area
A49: • TENANT_ESTIMATE: | D49: Tenant improvement cost estimates
...

Sheet README_Instructions
B2: RJK CONSTRUCTION - BUDGET TRACKER
B3: Purpose:
B4: This workbook is the new required standard for all budgeting, estimating, job tracking, and forecasting of any kind for construction projects at RJ Kelly.
B6: Color Legend:
B7: Cells in blue font are for manual input by Project Managers. All other cells are locked.
B8: Cells in black font are formula's and are not able to be edited
B10: Workflow:
B11: Step 1: Job Setup: Navigate to '01_Job Setup' tab and fill in the project's high-level details and scope of work.
B12: Step 2: Build Forecast & Budget: Use Commitment, Estimate, and Budget Logs to create Forecast and Budget amounts that populate in '05_Budget_Report'. Based on Cost Code Category and Vendor. -'02_Commitment_Log' : Record Subcontracts, Subcontract Change Orders, and Material Purchase Orders. Feeds into PM Forecast when 'Approved' status. -'03_PCC_Log' : Record Probably Construction Cost (PCC) estimates. Feeds into PM Forecast when 'Approved' status. -'04_Budget_Log' : Record Original Budget and any Budget changes. Feeds into Original and Revised Budget.
B14: Step 3: Tracking and Updating Budget: Track & Forecast: As the job progresses: - Log all contracts and POs in the '03_Commitment_Log'. - Log all budget changes in the '04_Change_Order_Log'. - Regularly update the 'Invoiced Cost' and 'PM Forecasted Final Cost' columns on the '02_Budget_Forecast' sheet to maintain an accurate projection.
N20: PROJECT COST MANAGEMENT WORKBOOK - COMPREHENSIVE README
N21: Generated: 2025-07-20 00:29 UTC
N23: OVERVIEW
N24: This workbook is RJK Construction's standardized project cost management system for budget tracking, forecasting, and financial reporting of construction projects. It integrates job setup parameters, commitment logging, potential cost tracking, and budget management into a comprehensive dashboard that provides real-time budget vs. actual analysis with Power Pivot data model integration for historical invoice tracking.
N26: WORKBOOK STRUCTURE
N27: • Total Sheets: 11
N28: • Structured Tables: 8 (tblCommitments, tblPotentialCosts, tblBudetLog, tblBudget, tblProperties, tblVendors, tblCostCodes, tblLookups, ProjectManagers)
N29: • Power Pivot Data Model: Yes (ThisWorkbookDataModel with CUBE formulas)
N30: • VBA Macros: None
N31: • Charts: None currently
N33: SHEET-BY-SHEET GUIDE
N34: 1. README_Instructions
... N219: • Recommended naming: ProjectName_BudgetTracker_v1.0.xlsx

Sheet 00_JobSetup
B2: Job Setup
B3: Property: | C3: 40mallrd
B4: Job Name: | C4: 40 Mall Rd Ste 206 PreTI
B5: Job SF: | C5: 1328
B6: Project Manager: | C6: Craig Sorbello
B7: Job Status: | C7: IN PROGRESS
B8: Job Type: | C8: PRE TI
B9: Projected Start Date: | D9: Boots in ground? Permit submitted? When?
B10: Projected Completion Date: | D10: C of O?
B11: Yardi Job Code: | C11: dev-23
B12: Scope of Work:
B16: Fee/Contingency Setup
B17: CM Fee % : | D17: 007400 - Construction Management Fee
B18: GC Fee % : | D18: 007200 - GC Fee
B19: GC Insurance % : | D19: 007316 - GC Insurance
B20: Dev Fee Type : | D20: n/a
B21: Dev Fee $ : | D21: 001900 - Development Fee
B22: Dev Fee % : | D22: 001900 - Development Fee
B23: Soft Cost Contingency % : | D23: 001099 - Soft Costs - Other
B24: Owner Contingency % : | D24: 001980 - Owner Const Cost Contingency
B25: GC Contingency % : | D25: 012116 - GC Cost Contingency
B27: Billing Setup
B28: Client/Tenant: | C28: n/a
B29: Form Type: | C29: n/a | D29: Estimate, invoice, pay app
B30: Invoice Date:
B31: Invoice /AIA #:

Sheet 01_ForecastLog
B2: FORECAST LOG
B3: ='00_JobSetup'!$C$4 -> 40 Mall Rd Ste 206 PreTI
B4: =INDEX(tblProperties[#All],MATCH('00_JobSetup'!$C$3,tblProperties[[#All],[PropertyCode]],0),2) -> 40 Mall Road
B5: ='00_JobSetup'!C5 -> 1328 | G5: maybe remove?
B7: Vendor | C7: Category | D7: Forecasted Cost Type | E7: Forecasted Cost Amount | F7: Forecasted Cost Status | G7: Date Entered | H7: Commitment Notes
B8: 3 Phase Elevator Corp. | C8: 140010 - Elevator | D8: Initial Estimate | E8: 4000 | F8: Pending
B9: A & M Roofing & Sheet Metal Co., Inc
B10: Boucher Acoustic LLC | C10: 095000 - Ceilings | D10: Subcontract | E10: 6140 | F10: Accepted | G10: 45866 | M10: Vendor | N10: Category | O10: Forecasted Cost Type | P10: Forecasted Cost Amount | Q10: Forecasted Cost Status | R10: Date Entered | S10: Commitment Notes
B11: Commercial Fire Sprinkler, Inc. | C11: 210010 - Fire Suppression - Total | D11: Subcontract | E11: 3900 | F11: Accepted | G11: 45866
B12: GSD Associates, LLC | C12: 001010 - Architect Fee | D12: Purchase Order | E12: 4000
B13: Lapery Painting | C13: 099000 - Painting and Coating | D13: Subcontract | E13: 3940 | F13: Accepted | G13: 45866 | M13: Vendor
B14: Lapery Painting | C14: 099000 - Painting and Coating | D14: Subcontract CO #1 | E14: 1000 | F14: Accepted | M14: Category
B15: Paglia Plastering, Inc. | C15: 092000 - Framing and Drywall | D15: Subcontract | E15: 10100 | F15: Accepted | G15: 45866 | M15: Forecasted Cost Type
B16: Precision Demolition, Inc. | C16: 024000 - Demo - Total | D16: Subcontract | E16: 3100 | F16: Accepted | G16: 45866 | M16: Forecasted Cost Amount
B17: R&M Glass LLC | C17: 084300 - Storefronts | D17: Subcontract | E17: 1806 | F17: Accepted | G17: 45866 | M17: Forecasted Cost Status
B18: R&M Glass LLC | C18: 084300 - Storefronts | D18: Subcontract CO #1 | E18: 1806 | F18: Accepted | G18: 45866 | H18: added 6 windows | M18: Commitment Notes
B19: Rizzo's Floor Covering | C19: 096000 - Flooring | D19: Subcontract | E19: 500 | F19: Accepted | G19: 45866
B20: RJK Company, Inc. | C20: 008010 - Labor - Project Manager
B21: Systems Electrical Services Co., Inc. | C21: 260010 - Electrical - Total | D21: Subcontract | E21: 9325 | F21: Accepted | G21: 45866
B22: Able Air Corp
D38: FORECAST AMOUNT: | E38: =SUBTOTAL(109,tblForecastLog[Forecasted Cost Amount]) -> 49617

Sheet 04_VendorDetail
C2: Vendor Detail
C3: ='00_JobSetup'!C4 -> 40 Mall Rd Ste 206 PreTI
C4: =INDEX(tblProperties[#All],MATCH('00_JobSetup'!$C$3,tblProperties[[#All],[PropertyCode]],0),2) -> 40 Mall Road
C5: ='00_JobSetup'!C5 -> 1328
C7: Vendor Name | D7: Subcontract | E7: Change Orders | F7: Purchase Orders | G7: Total Committed | H7: Estimated Cost | I7: Invoiced to Date | J7: Project Manger Notes
A8: 3 Phase Elevator Corp. | B8: {=_xlfn.LET(_xlpm.idx,ROW()-ROW('04_VendorDetail'!$C$7),IFERROR(INDEX(Vendor_Name_index,_xlpm.idx),""))} | C8: {=_xlfn.LET(_xlpm.trig,RAND()*0,_xlpm.flList,_xlfn._xlws.FILTER(tblForecastLog[Vendor],tblForecastLog[Vendor]<>""),_xlpm.cubeSet,CUBESET("ThisWorkbookDataModel","[Fact_JobDetail].[_Vendor].Members"),_xlpm.setCnt,CUBESETCOUNT(_xlpm.cubeSet),_xlpm.dmRaw,_xlfn.MAP(_xlfn.SEQUENCE(_xlpm.setCnt),_xlfn.LAMBDA(_xlpm.i,IFERROR(CUBERANKEDMEMBER("ThisWorkbookDataModel",_xlpm.cubeSet,_xlpm.i),""))),_xlpm.dmList,_xlfn._xlws.FILTER(_xlpm.dmRaw,(_xlpm.dmRaw<>"")*(_xlpm.dmRaw<>"All")),_xlpm.combined,_xlfn.VSTACK(_xlpm.flList,_xlpm.dmList),_xlfn._xlws.SORT(_xlfn.UNIQUE(_xlpm.combined)))} -> #N/A | D8: =SUMIFS(tblForecastLog[Forecasted Cost Amount],tblForecastLog[Vendor],A8,tblForecastLog[Forecasted Cost Type],"Subcontract") -> 0 | E8: {=SUMPRODUCT((tblForecastLog[Vendor]=A8)*(ISNUMBER(SEARCH("CO",tblForecastLog[Forecasted Cost Type])))*(tblForecastLog[Forecasted Cost Amount]))+SUMIFS(tblForecastLog[Forecasted Cost Amount],tblForecastLog[Vendor],A8,tblForecastLog[Forecasted Cost Type],"Change Order")} -> 0 | F8: =SUMIFS(tblForecastLog[Forecasted Cost Amount],tblForecastLog[Vendor],A8,tblForecastLog[Forecasted Cost Type],"Purchase Order") -> 0 | G8: =SUM(D8:F8) -> 0 | H8: =SUMIF(tblForecastLog[Vendor],A8,tblForecastLog[Forecasted Cost Amount]) -> 4000 | I8: =_xlfn.IFNA(CUBEVALUE("ThisWorkbookDataModel","[Measures].[Amount by Vendor]",CUBEMEMBER("ThisWorkbookDataModel","[Fact_JobDetail].[_Vendor].&["&TRIM($C8)&"]")),0) -> 0
A9: A & M Roofing & Sheet Metal Co., Inc | D9: =SUMIFS(tblForecastLog[Forecasted Cost Amount],tblForecastLog[Vendor],A9,tblForecastLog[Forecasted Cost Type],"Subcontract") -> 0 | E9: {=SUMPRODUCT((tblForecastLog[Vendor]=A9)*(ISNUMBER(SEARCH("CO",tblForecastLog[Forecasted Cost Type])))*(tblForecastLog[Forecasted Cost Amount]))+SUMIFS(tblForecastLog[Forecasted Cost Amount],tblForecastLog[Vendor],A9,tblForecastLog[Forecasted Cost Type],"Change Order")} -> 0 | F9: =SUMIFS(tblForecastLog[Forecasted Cost Amount],tblForecastLog[Vendor],A9,tblForecastLog[Forecasted Cost Type],"Purchase Order") -> 0 | G9: =SUM(D9:F9) -> 0 | H9: =SUMIF(tblForecastLog[Vendor],A9,tblForecastLog[Forecasted Cost Amount]) -> 0 | I9: =_xlfn.IFNA(CUBEVALUE("ThisWorkbookDataModel","[Measures].[Amount by Vendor]",CUBEMEMBER("ThisWorkbookDataModel","[Fact_JobDetail].[_Vendor].&["&TRIM($C9)&"]")),0) -> 0
A10: Boucher Acoustic LLC | D10: =SUMIFS(tblForecastLog[Forecasted Cost Amount],tblForecastLog[Vendor],A10,tblForecastLog[Forecasted Cost Type],"Subcontract") -> 6140 | E10: {=SUMPRODUCT((tblForecastLog[Vendor]=A10)*(ISNUMBER(SEARCH("CO",tblForecastLog[Forecasted Cost Type])))*(tblForecastLog[Forecasted Cost Amount]))+SUMIFS(tblForecastLog[Forecasted Cost Amount],tblForecastLog[Vendor],A10,tblForecastLog[Forecasted Cost Type],"Change Order")} -> 6140 | F10: =SUMIFS(tblForecastLog[Forecasted Cost Amount],tblForecastLog[Vendor],A10,tblForecastLog[Forecasted Cost Type],"Purchase Order") -> 0 | G10: =SUM(D10:F10) -> 12280 | H10: =SUMIF(tblForecastLog[Vendor],A10,tblForecastLog[Forecasted Cost Amount]) -> 6140 | I10: =_xlfn.IFNA(CUBEVALUE("ThisWorkbookDataModel","[Measures].[Amount by Vendor]",CUBEMEMBER("ThisWorkbookDataModel","[Fact_JobDetail].[_Vendor].&["&TRIM($C10)&"]")),0) -> 0
A11: Commercial Fire Sprinkler, Inc. | D11: =SUMIFS(tblForecastLog[Forecasted Cost Amount],tblForecastLog[Vendor],A11,tblForecastLog[Forecasted Cost Type],"Subcontract") -> 3900 | E11: {=SUMPRODUCT((tblForecastLog[Vendor]=A11)*(ISNUMBER(SEARCH("CO",tblForecastLog[Forecasted Cost Type])))*(tblForecastLog[Forecasted Cost Amount]))+SUMIFS(tblForecastLog[Forecasted Cost Amount],tblForecastLog[Vendor],A11,tblForecastLog[Forecasted Cost Type],"Change Order")} -> 3900 | F11: =SUMIFS(tblForecastLog[Forecasted Cost Amount],tblForecastLog[Vendor],A11,tblForecastLog[Forecasted Cost Type],"Purchase Order") -> 0 | G11: =SUM(D11:F11) -> 7800 | H11: =SUMIF(tblForecastLog[Vendor],A11,tblForecastLog[Forecasted Cost Amount]) -> 3900 | I11: =_xlfn.IFNA(CUBEVALUE("ThisWorkbookDataModel","[Measures].[Amount by Vendor]",CUBEMEMBER("ThisWorkbookDataModel","[Fact_JobDetail].[_Vendor].&["&TRIM($C11)&"]")),0) -> 0
A12: GSD Associates, LLC | D12: =SUMIFS(tblForecastLog[Forecasted Cost Amount],tblForecastLog[Vendor],A12,tblForecastLog[Forecasted Cost Type],"Subcontract") -> 0 | E12: {=SUMPRODUCT((tblForecastLog[Vendor]=A12)*(ISNUMBER(SEARCH("CO",tblForecastLog[Forecasted Cost Type])))*(tblForecastLog[Forecasted Cost Amount]))+SUMIFS(tblForecastLog[Forecasted Cost Amount],tblForecastLog[Vendor],A12,tblForecastLog[Forecasted Cost Type],"Change Order")} -> 0 | F12: =SUMIFS(tblForecastLog[Forecasted Cost Amount],tblForecastLog[Vendor],A12,tblForecastLog[Forecasted Cost Type],"Purchase Order") -> 4000 | G12: =SUM(D12:F12) -> 4000 | H12: =SUMIF(tblForecastLog[Vendor],A12,tblForecastLog[Forecasted Cost Amount]) -> 4000 | I12: =_xlfn.IFNA(CUBEVALUE("ThisWorkbookDataModel","[Measures].[Amount by Vendor]",CUBEMEMBER("ThisWorkbookDataModel","[Fact_JobDetail].[_Vendor].&["&TRIM($C12)&"]")),0) -> 0
A13: Lapery Painting | D13: =SUMIFS(tblForecastLog[Forecasted Cost Amount],tblForecastLog[Vendor],A13,tblForecastLog[Forecasted Cost Type],"Subcontract") -> 3940 | E13: {=SUMPRODUCT((tblForecastLog[Vendor]=A13)*(ISNUMBER(SEARCH("CO",tblForecastLog[Forecasted Cost Type])))*(tblForecastLog[Forecasted Cost Amount]))+SUMIFS(tblForecastLog[Forecasted Cost Amount],tblForecastLog[Vendor],A13,tblForecastLog[Forecasted Cost Type],"Change Order")} -> 4940 | F13: =SUMIFS(tblForecastLog[Forecasted Cost Amount],tblForecastLog[Vendor],A13,tblForecastLog[Forecasted Cost Type],"Purchase Order") -> 0 | G13: =SUM(D13:F13) -> 8880 | H13: =SUMIF(tblForecastLog[Vendor],A13,tblForecastLog[Forecasted Cost Amount]) -> 4940 | I13: =_xlfn.IFNA(CUBEVALUE("ThisWorkbookDataModel","[Measures].[Amount by Vendor]",CUBEMEMBER("ThisWorkbookDataModel","[Fact_JobDetail].[_Vendor].&["&TRIM($C13)&"]")),0) -> 0
A14: Paglia Plastering, Inc. | D14: =SUMIFS(tblForecastLog[Forecasted Cost Amount],tblForecastLog[Vendor],A14,tblForecastLog[Forecasted Cost Type],"Subcontract") -> 10100 | E14: {=SUMPRODUCT((tblForecastLog[Vendor]=A14)*(ISNUMBER(SEARCH("CO",tblForecastLog[Forecasted Cost Type])))*(tblForecastLog[Forecasted Cost Amount]))+SUMIFS(tblForecastLog[Forecasted Cost Amount],tblForecastLog[Vendor],A14,tblForecastLog[Forecasted Cost Type],"Change Order")} -> 10100 | F14: =SUMIFS(tblForecastLog[Forecasted Cost Amount],tblForecastLog[Vendor],A14,tblForecastLog[Forecasted Cost Type],"Purchase Order") -> 0 | G14: =SUM(D14:F14) -> 20200 | H14: =SUMIF(tblForecastLog[Vendor],A14,tblForecastLog[Forecasted Cost Amount]) -> 10100 | I14: =_xlfn.IFNA(CUBEVALUE("ThisWorkbookDataModel","[Measures].[Amount by Vendor]",CUBEMEMBER("ThisWorkbookDataModel","[Fact_JobDetail].[_Vendor].&["&TRIM($C14)&"]")),0) -> 0
A15: Precision Demolition, Inc. | D15: =SUMIFS(tblForecastLog[Forecasted Cost Amount],tblForecastLog[Vendor],A15,tblForecastLog[Forecasted Cost Type],"Subcontract") -> 3100 | E15: {=SUMPRODUCT((tblForecastLog[Vendor]=A15)*(ISNUMBER(SEARCH("CO",tblForecastLog[Forecasted Cost Type])))*(tblForecastLog[Forecasted Cost Amount]))+SUMIFS(tblForecastLog[Forecasted Cost Amount],tblForecastLog[Vendor],A15,tblForecastLog[Forecasted Cost Type],"Change Order")} -> 3100 | F15: =SUMIFS(tblForecastLog[Forecasted Cost Amount],tblForecastLog[Vendor],A15,tblForecastLog[Forecasted Cost Type],"Purchase Order") -> 0 | G15: =SUM(D15:F15) -> 6200 | H15: =SUMIF(tblForecastLog[Vendor],A15,tblForecastLog[Forecasted Cost Amount]) -> 3100 | I15: =_xlfn.IFNA(CUBEVALUE("ThisWorkbookDataModel","[Measures].[Amount by Vendor]",CUBEMEMBER("ThisWorkbookDataModel","[Fact_JobDetail].[_Vendor].&["&TRIM($C15)&"]")),0) -> 0
A16: R&M Glass LLC | D16: =SUMIFS(tblForecastLog[Forecasted Cost Amount],tblForecastLog[Vendor],A16,tblForecastLog[Forecasted Cost Type],"Subcontract") -> 1806 | E16: {=SUMPRODUCT((tblForecastLog[Vendor]=A16)*(ISNUMBER(SEARCH("CO",tblForecastLog[Forecasted Cost Type])))*(tblForecastLog[Forecasted Cost Amount]))+SUMIFS(tblForecastLog[Forecasted Cost Amount],tblForecastLog[Vendor],A16,tblForecastLog[Forecasted Cost Type],"Change Order")} -> 3612 | F16: =SUMIFS(tblForecastLog[Forecasted Cost Amount],tblForecastLog[Vendor],A16,tblForecastLog[Forecasted Cost Type],"Purchase Order") -> 0 | G16: =SUM(D16:F16) -> 5418 | H16: =SUMIF(tblForecastLog[Vendor],A16,tblForecastLog[Forecasted Cost Amount]) -> 3612 | I16: =_xlfn.IFNA(CUBEVALUE("ThisWorkbookDataModel","[Measures].[Amount by Vendor]",CUBEMEMBER("ThisWorkbookDataModel","[Fact_JobDetail].[_Vendor].&["&TRIM($C16)&"]")),0) -> 0
A17: Rizzo's Floor Covering | D17: =SUMIFS(tblForecastLog[Forecasted Cost Amount],tblForecastLog[Vendor],A17,tblForecastLog[Forecasted Cost Type],"Subcontract") -> 500 | E17: {=SUMPRODUCT((tblForecastLog[Vendor]=A17)*(ISNUMBER(SEARCH("CO",tblForecastLog[Forecasted Cost Type])))*(tblForecastLog[Forecasted Cost Amount]))+SUMIFS(tblForecastLog[Forecasted Cost Amount],tblForecastLog[Vendor],A17,tblForecastLog[Forecasted Cost Type],"Change Order")} -> 500 | F17: =SUMIFS(tblForecastLog[Forecasted Cost Amount],tblForecastLog[Vendor],A17,tblForecastLog[Forecasted Cost Type],"Purchase Order") -> 0 | G17: =SUM(D17:F17) -> 1000 | H17: =SUMIF(tblForecastLog[Vendor],A17,tblForecastLog[Forecasted Cost Amount]) -> 500 | I17: =_xlfn.IFNA(CUBEVALUE("ThisWorkbookDataModel","[Measures].[Amount by Vendor]",CUBEMEMBER("ThisWorkbookDataModel","[Fact_JobDetail].[_Vendor].&["&TRIM($C17)&"]")),0) -> 0
A18: RJK Company, Inc. | D18: =SUMIFS(tblForecastLog[Forecasted Cost Amount],tblForecastLog[Vendor],A18,tblForecastLog[Forecasted Cost Type],"Subcontract") -> 0 | E18: {=SUMPRODUCT((tblForecastLog[Vendor]=A18)*(ISNUMBER(SEARCH("CO",tblForecastLog[Forecasted Cost Type])))*(tblForecastLog[Forecasted Cost Amount]))+SUMIFS(tblForecastLog[Forecasted Cost Amount],tblForecastLog[Vendor],A18,tblForecastLog[Forecasted Cost Type],"Change Order")} -> 0 | F18: =SUMIFS(tblForecastLog[Forecasted Cost Amount],tblForecastLog[Vendor],A18,tblForecastLog[Forecasted Cost Type],"Purchase Order") -> 0 | G18: =SUM(D18:F18) -> 0 | H18: =SUMIF(tblForecastLog[Vendor],A18,tblForecastLog[Forecasted Cost Amount]) -> 0 | I18: =_xlfn.IFNA(CUBEVALUE("ThisWorkbookDataModel","[Measures].[Amount by Vendor]",CUBEMEMBER("ThisWorkbookDataModel","[Fact_JobDetail].[_Vendor].&["&TRIM($C18)&"]")),0) -> 0
A19: Systems Electrical Services Co., Inc. | D19: =SUMIFS(tblForecastLog[Forecasted Cost Amount],tblForecastLog[Vendor],A19,tblForecastLog[Forecasted Cost Type],"Subcontract") -> 9325 | E19: {=SUMPRODUCT((tblForecastLog[Vendor]=A19)*(ISNUMBER(SEARCH("CO",tblForecastLog[Forecasted Cost Type])))*(tblForecastLog[Forecasted Cost Amount]))+SUMIFS(tblForecastLog[Forecasted Cost Amount],tblForecastLog[Vendor],A19,tblForecastLog[Forecasted Cost Type],"Change Order")} -> 9325 | F19: =SUMIFS(tblForecastLog[Forecasted Cost Amount],tblForecastLog[Vendor],A19,tblForecastLog[Forecasted Cost Type],"Purchase Order") -> 0 | G19: =SUM(D19:F19) -> 18650 | H19: =SUMIF(tblForecastLog[Vendor],A19,tblForecastLog[Forecasted Cost Amount]) -> 9325 | I19: =_xlfn.IFNA(CUBEVALUE("ThisWorkbookDataModel","[Measures].[Amount by Vendor]",CUBEMEMBER("ThisWorkbookDataModel","[Fact_JobDetail].[_Vendor].&["&TRIM($C19)&"]")),0) -> 0
A20: Able Air Corp | D20: =SUMIFS(tblForecastLog[Forecasted Cost Amount],tblForecastLog[Vendor],A20,tblForecastLog[Forecasted Cost Type],"Subcontract") -> 0 | E20: {=SUMPRODUCT((tblForecastLog[Vendor]=A20)*(ISNUMBER(SEARCH("CO",tblForecastLog[Forecasted Cost Type])))*(tblForecastLog[Forecasted Cost Amount]))+SUMIFS(tblForecastLog[Forecasted Cost Amount],tblForecastLog[Vendor],A20,tblForecastLog[Forecasted Cost Type],"Change Order")} -> 0 | F20: =SUMIFS(tblForecastLog[Forecasted Cost Amount],tblForecastLog[Vendor],A20,tblForecastLog[Forecasted Cost Type],"Purchase Order") -> 0 | G20: =SUM(D20:F20) -> 0 | H20: =SUMIF(tblForecastLog[Vendor],A20,tblForecastLog[Forecasted Cost Amount]) -> 0 | I20: =_xlfn.IFNA(CUBEVALUE("ThisWorkbookDataModel","[Measures].[Amount by Vendor]",CUBEMEMBER("ThisWorkbookDataModel","[Fact_JobDetail].[_Vendor].&["&TRIM($C20)&"]")),0) -> 0
A21: GSD Associates, LLC | D21: =SUMIFS(tblForecastLog[Forecasted Cost Amount],tblForecastLog[Vendor],A21,tblForecastLog[Forecasted Cost Type],"Subcontract") -> 0 | E21: {=SUMPRODUCT((tblForecastLog[Vendor]=A21)*(ISNUMBER(SEARCH("CO",tblForecastLog[Forecasted Cost Type])))*(tblForecastLog[Forecasted Cost Amount]))+SUMIFS(tblForecastLog[Forecasted Cost Amount],tblForecastLog[Vendor],A21,tblForecastLog[Forecasted Cost Type],"Change Order")} -> 0 | F21: =SUMIFS(tblForecastLog[Forecasted Cost Amount],tblForecastLog[Vendor],A21,tblForecastLog[Forecasted Cost Type],"Purchase Order") -> 4000 | G21: =SUM(D21:F21) -> 4000 | H21: =SUMIF(tblForecastLog[Vendor],A21,tblForecastLog[Forecasted Cost Amount]) -> 4000 | I21: =_xlfn.IFNA(CUBEVALUE("ThisWorkbookDataModel","[Measures].[Amount by Vendor]",CUBEMEMBER("ThisWorkbookDataModel","[Fact_JobDetail].[_Vendor].&["&TRIM($C21)&"]")),0) -> 0
I22: =_xlfn.IFNA(CUBEVALUE("ThisWorkbookDataModel","[Measures].[Amount by Vendor]",CUBEMEMBER("ThisWorkbookDataModel","[Fact_JobDetail].[_Vendor].&["&TRIM($C22)&"]")),0) -> 0 | L22: {=_xlfn.LET(_xlpm.cubeSet,CUBESET("ThisWorkbookDataModel","[Fact_JobDetail].[_Vendor].Members"),_xlfn.MAP(_xlfn.SEQUENCE(CUBESETCOUNT(_xlpm.cubeSet)),_xlfn.LAMBDA(_xlpm.i,CUBERANKEDMEMBER("ThisWorkbookDataModel",_xlpm.cubeSet,_xlpm.i))))} -> #N/A
I23: =_xlfn.IFNA(CUBEVALUE("ThisWorkbookDataModel","[Measures].[Amount by Vendor]",CUBEMEMBER("ThisWorkbookDataModel","[Fact_JobDetail].[_Vendor].&["&TRIM($C23)&"]")),0) -> 0
I24: =_xlfn.IFNA(CUBEVALUE("ThisWorkbookDataModel","[Measures].[Amount by Vendor]",CUBEMEMBER("ThisWorkbookDataModel","[Fact_JobDetail].[_Vendor].&["&TRIM($C24)&"]")),0) -> 0
I25: =_xlfn.IFNA(CUBEVALUE("ThisWorkbookDataModel","[Measures].[Amount by Vendor]",CUBEMEMBER("ThisWorkbookDataModel","[Fact_JobDetail].[_Vendor].&["&TRIM($C25)&"]")),0) -> 0
D92: =SUBTOTAL(109,'04_VendorDetail'!$D$8:$D$91) -> 38811 | F92: =SUBTOTAL(109,'04_VendorDetail'!$F$8:$F$91) -> 8000 | G92: =SUBTOTAL(109,'04_VendorDetail'!$G$8:$G$91) -> 88428 | H92: =SUBTOTAL(109,'04_VendorDetail'!$H$8:$H$91) -> 53617 | I92: =SUBTOTAL(109,'04_VendorDetail'!$I$8:$I$91) -> 0

Sheet 02_BudgetLog
B2: BUDGET LOG
B3: ='03_BudgetReport'!B3 -> 40 Mall Rd Ste 206 PreTI
B4: =INDEX(tblProperties[#All],MATCH('00_JobSetup'!$C$3,tblProperties[[#All],[PropertyCode]],0),2) -> 40 Mall Road
B5: ='00_JobSetup'!C5 -> 1328
B7: Category | C7: Budget Type | D7: Budget Amount | E7: Budget Status | F7: Date Entered | G7: Budget Notes
B8: 001100 - Building Permits and Fees | C8: Original Budget | D8: 686.63 | E8: Approved | F8: 45866 | G8: Initial PM Forecast
B9: 008010 - Labor - Project Manager | C9: Original Budget | D9: 3700 | E9: Approved | F9: 45866 | G9: Initial PM Forecast
B10: 008020 - Labor - Super | C10: Original Budget | D10: 2700 | E10: Approved | F10: 45866 | G10: Initial PM Forecast
B11: 008030 - Labor - Foreman | C11: Original Budget | D11: 1440 | E11: Approved | F11: 45866 | G11: Initial PM Forecast
B12: 008050 - Labor - General Labor | C12: Original Budget | D12: 960 | E12: Approved | F12: 45866 | G12: Initial PM Forecast
B13: 010010 - General Requirements - Total | C13: Original Budget | D13: 1558.56 | E13: Approved | F13: 45866 | G13: Initial PM Forecast
B14: 024000 - Demo - Total | C14: Original Budget | D14: 3100 | E14: Approved | F14: 45866 | G14: Initial PM Forecast
B15: 081000 - Doors, Frames, & Hardware | C15: Original Budget | D15: 4500 | E15: Approved | F15: 45866 | G15: Initial PM Forecast
B16: 084300 - Storefronts | C16: Original Budget | D16: 1806 | E16: Approved | F16: 45866 | G16: Initial PM Forecast
B17: 084400 - Blinds | C17: Original Budget | D17: 1050 | E17: Approved | F17: 45866 | G17: Initial PM Forecast
B18: 092000 - Framing and Drywall | C18: Original Budget | D18: 10100 | E18: Approved | F18: 45866 | G18: Initial PM Forecast
B19: 095000 - Ceilings | C19: Original Budget | D19: 6140 | E19: Approved | F19: 45866 | G19: Initial PM Forecast
... B24: 260010 - Electrical - Total | C24: Original Budget | D24: 9325 | E24: Approved | F24: 45866 | G24: Initial PM Forecast
B67: Total | D67: =SUBTOTAL(109,tblBudetLog[Budget Amount]) -> 57906.19

Sheet 03_BudgetReport
B2: BUDGET REPORT
B3: ='00_JobSetup'!C4 -> 40 Mall Rd Ste 206 PreTI
B4: =INDEX(tblProperties[#All],MATCH('00_JobSetup'!$C$3,tblProperties[[#All],[PropertyCode]],0),2) -> 40 Mall Road
B5: ='00_JobSetup'!C5 -> 1328
C6: (1) | D6: (2) | E6: (1)+(2)= (3) | G6: (a) | H6: (b) | I6: (a)+(b)= (c) | K6: (c) - (3)
B7: Category | C7: Original Budget | D7: Approved Changes | E7: Revised Budget | F7: Revised Budget PSF | G7: Committed Cost | H7: Estimated Costs | I7: Forecasted Final Cost | J7: Forecasted Cost PSF | K7: Forecasted (Over)/Under | L7: Invoiced to Date | M7: Project Manger Notes
B8: {=_xlfn.LET(_xlpm.trig,RAND()*0,_xlpm.wbRaw,_xlfn.VSTACK(tblForecastLog[Category],tblBudetLog[Category]),_xlpm.wbList,_xlfn._xlws.SORT(_xlfn.UNIQUE(_xlfn._xlws.FILTER(_xlpm.wbRaw,_xlpm.wbRaw<>""))),_xlpm.cubeSet,CUBESET("ThisWorkbookDataModel","[Fact_JobDetail].[_Category].Members"),_xlpm.setCnt,CUBESETCOUNT(_xlpm.cubeSet),_xlpm.dmList,_xlfn.MAP(_xlfn.SEQUENCE(_xlpm.setCnt),_xlfn.LAMBDA(_xlpm.i,CUBERANKEDMEMBER("ThisWorkbookDataModel",_xlpm.cubeSet,_xlpm.i))),_xlpm.fullList,_xlfn._xlws.SORT(_xlfn.UNIQUE(_xlfn._xlws.FILTER(_xlfn.VSTACK(_xlpm.wbList,_xlpm.dmList),_xlfn.VSTACK(_xlpm.wbList,_xlpm.dmList)<>"All"))),_xlpm.idx,ROW()-ROW(tblBudget[[#Headers],[Category]]),IFERROR(INDEX(_xlpm.fullList,_xlpm.idx),""))} | C8: =SUMIFS(tblBudetLog[Budget Amount],tblBudetLog[Category],tblBudget[[#This Row],[Category]],tblBudetLog[Budget Type],"Original Budget",tblBudetLog[Budget Status],"Approved") -> 0 | D8: =SUMIFS(tblBudetLog[Budget Amount],tblBudetLog[Category],tblBudget[[#This Row],[Category]],tblBudetLog[Budget Type],"Budget Adjustment") -> 0 | E8: =tblBudget[[#This Row],[Original Budget]]+tblBudget[[#This Row],[Approved Changes]] -> 0 | F8: =tblBudget[[#This Row],[Revised Budget]]/$B$5 -> 0 | G8: {=SUMPRODUCT((tblForecastLog[Category]=tblBudget[[#This Row],[Category]])*ISNUMBER(MATCH(tblForecastLog[Forecasted Cost Type],{"Actual Cost","Purchase Order","Subcontract","Subcontract CO #1","Subcontract CO #2","Subcontract CO #3","Subcontract CO #4","Subcontract CO #5","Subcontract CO #6","Subcontract CO #7","Subcontract CO #8","Subcontract CO #9","Subcontract CO #10"},0))*(tblForecastLog[Forecasted Cost Status]="Accepted")*tblForecastLog[Forecasted Cost Amount])} -> 0 | H8: {=SUMPRODUCT((tblForecastLog[Category]=tblBudget[[#This Row],[Category]])*ISNUMBER(MATCH(tblForecastLog[Forecasted Cost Type],{"Initial Estimate","Revised Estimate"},0))*ISNUMBER(MATCH(tblForecastLog[Forecasted Cost Status],{"Accepted","Pending"},0))*tblForecastLog[Forecasted Cost Amount])} -> 0 | I8: =tblBudget[[#This Row],[Committed Cost]]+tblBudget[[#This Row],[Estimated Costs]] -> 0 | J8: =tblBudget[[#This Row],[Forecasted Final Cost]]/$B$5 -> 0 | K8: =tblBudget[[#This Row],[Revised Budget]]-tblBudget[[#This Row],[Forecasted Final Cost]] -> 0 | L8: =_xlfn.IFNA(CUBEVALUE("ThisWorkbookDataModel","[Measures].[Amount by _Category]",CUBEMEMBER("ThisWorkbookDataModel","[Fact_JobDetail].[_Category].&["&TRIM($B8)&"]")),0) -> 0
B9: {=_xlfn.LET(_xlpm.trig,RAND()*0,_xlpm.wbRaw,_xlfn.VSTACK(tblForecastLog[Category],tblBudetLog[Category]),_xlpm.wbList,_xlfn._xlws.SORT(_xlfn.UNIQUE(_xlfn._xlws.FILTER(_xlpm.wbRaw,_xlpm.wbRaw<>""))),_xlpm.cubeSet,CUBESET("ThisWorkbookDataModel","[Fact_JobDetail].[_Category].Members"),_xlpm.setCnt,CUBESETCOUNT(_xlpm.cubeSet),_xlpm.dmList,_xlfn.MAP(_xlfn.SEQUENCE(_xlpm.setCnt),_xlfn.LAMBDA(_xlpm.i,CUBERANKEDMEMBER("ThisWorkbookDataModel",_xlpm.cubeSet,_xlpm.i))),_xlpm.fullList,_xlfn._xlws.SORT(_xlfn.UNIQUE(_xlfn._xlws.FILTER(_xlfn.VSTACK(_xlpm.wbList,_xlpm.dmList),_xlfn.VSTACK(_xlpm.wbList,_xlpm.dmList)<>"All"))),_xlpm.idx,ROW()-ROW(tblBudget[[#Headers],[Category]]),IFERROR(INDEX(_xlpm.fullList,_xlpm.idx),""))} | C9: =SUMIFS(tblBudetLog[Budget Amount],tblBudetLog[Category],tblBudget[[#This Row],[Category]],tblBudetLog[Budget Type],"Original Budget",tblBudetLog[Budget Status],"Approved") -> 0 | D9: =SUMIFS(tblBudetLog[Budget Amount],tblBudetLog[Category],tblBudget[[#This Row],[Category]],tblBudetLog[Budget Type],"Budget Adjustment") -> 0 | E9: =tblBudget[[#This Row],[Original Budget]]+tblBudget[[#This Row],[Approved Changes]] -> 0 | F9: =tblBudget[[#This Row],[Revised Budget]]/$B$5 -> 0 | G9: {=SUMPRODUCT((tblForecastLog[Category]=tblBudget[[#This Row],[Category]])*ISNUMBER(MATCH(tblForecastLog[Forecasted Cost Type],{"Actual Cost","Purchase Order","Subcontract","Subcontract CO #1","Subcontract CO #2","Subcontract CO #3","Subcontract CO #4","Subcontract CO #5","Subcontract CO #6","Subcontract CO #7","Subcontract CO #8","Subcontract CO #9","Subcontract CO #10"},0))*(tblForecastLog[Forecasted Cost Status]="Accepted")*tblForecastLog[Forecasted Cost Amount])} -> 0 | H9: {=SUMPRODUCT((tblForecastLog[Category]=tblBudget[[#This Row],[Category]])*ISNUMBER(MATCH(tblForecastLog[Forecasted Cost Type],{"Initial Estimate","Revised Estimate"},0))*ISNUMBER(MATCH(tblForecastLog[Forecasted Cost Status],{"Accepted","Pending"},0))*tblForecastLog[Forecasted Cost Amount])} -> 0 | I9: =tblBudget[[#This Row],[Committed Cost]]+tblBudget[[#This Row],[Estimated Costs]] -> 0 | J9: =tblBudget[[#This Row],[Forecasted Final Cost]]/$B$5 -> 0 | K9: =tblBudget[[#This Row],[Revised Budget]]-tblBudget[[#This Row],[Forecasted Final Cost]] -> 0 | L9: =_xlfn.IFNA(CUBEVALUE("ThisWorkbookDataModel","[Measures].[Amount by _Category]",CUBEMEMBER("ThisWorkbookDataModel","[Fact_JobDetail].[_Category].&["&TRIM($B9)&"]")),0) -> 0
B10: {=_xlfn.LET(_xlpm.trig,RAND()*0,_xlpm.wbRaw,_xlfn.VSTACK(tblForecastLog[Category],tblBudetLog[Category]),_xlpm.wbList,_xlfn._xlws.SORT(_xlfn.UNIQUE(_xlfn._xlws.FILTER(_xlpm.wbRaw,_xlpm.wbRaw<>""))),_xlpm.cubeSet,CUBESET("ThisWorkbookDataModel","[Fact_JobDetail].[_Category].Members"),_xlpm.setCnt,CUBESETCOUNT(_xlpm.cubeSet),_xlpm.dmList,_xlfn.MAP(_xlfn.SEQUENCE(_xlpm.setCnt),_xlfn.LAMBDA(_xlpm.i,CUBERANKEDMEMBER("ThisWorkbookDataModel",_xlpm.cubeSet,_xlpm.i))),_xlpm.fullList,_xlfn._xlws.SORT(_xlfn.UNIQUE(_xlfn._xlws.FILTER(_xlfn.VSTACK(_xlpm.wbList,_xlpm.dmList),_xlfn.VSTACK(_xlpm.wbList,_xlpm.dmList)<>"All"))),_xlpm.idx,ROW()-ROW(tblBudget[[#Headers],[Category]]),IFERROR(INDEX(_xlpm.fullList,_xlpm.idx),""))} | C10: =SUMIFS(tblBudetLog[Budget Amount],tblBudetLog[Category],tblBudget[[#This Row],[Category]],tblBudetLog[Budget Type],"Original Budget",tblBudetLog[Budget Status],"Approved") -> 0 | D10: =SUMIFS(tblBudetLog[Budget Amount],tblBudetLog[Category],tblBudget[[#This Row],[Category]],tblBudetLog[Budget Type],"Budget Adjustment") -> 0 | E10: =tblBudget[[#This Row],[Original Budget]]+tblBudget[[#This Row],[Approved Changes]] -> 0 | F10: =tblBudget[[#This Row],[Revised Budget]]/$B$5 -> 0 | G10: {=SUMPRODUCT((tblForecastLog[Category]=tblBudget[[#This Row],[Category]])*ISNUMBER(MATCH(tblForecastLog[Forecasted Cost Type],{"Actual Cost","Purchase Order","Subcontract","Subcontract CO #1","Subcontract CO #2","Subcontract CO #3","Subcontract CO #4","Subcontract CO #5","Subcontract CO #6","Subcontract CO #7","Subcontract CO #8","Subcontract CO #9","Subcontract CO #10"},0))*(tblForecastLog[Forecasted Cost Status]="Accepted")*tblForecastLog[Forecasted Cost Amount])} -> 0 | H10: {=SUMPRODUCT((tblForecastLog[Category]=tblBudget[[#This Row],[Category]])*ISNUMBER(MATCH(tblForecastLog[Forecasted Cost Type],{"Initial Estimate","Revised Estimate"},0))*ISNUMBER(MATCH(tblForecastLog[Forecasted Cost Status],{"Accepted","Pending"},0))*tblForecastLog[Forecasted Cost Amount])} -> 0 | I10: =tblBudget[[#This Row],[Committed Cost]]+tblBudget[[#This Row],[Estimated Costs]] -> 0 | J10: =tblBudget[[#This Row],[Forecasted Final Cost]]/$B$5 -> 0 | K10: =tblBudget[[#This Row],[Revised Budget]]-tblBudget[[#This Row],[Forecasted Final Cost]] -> 0 | L10: =_xlfn.IFNA(CUBEVALUE("ThisWorkbookDataModel","[Measures].[Amount by _Category]",CUBEMEMBER("ThisWorkbookDataModel","[Fact_JobDetail].[_Category].&["&TRIM($B10)&"]")),0) -> 0
B11: {=_xlfn.LET(_xlpm.trig,RAND()*0,_xlpm.wbRaw,_xlfn.VSTACK(tblForecastLog[Category],tblBudetLog[Category]),_xlpm.wbList,_xlfn._xlws.SORT(_xlfn.UNIQUE(_xlfn._xlws.FILTER(_xlpm.wbRaw,_xlpm.wbRaw<>""))),_xlpm.cubeSet,CUBESET("ThisWorkbookDataModel","[Fact_JobDetail].[_Category].Members"),_xlpm.setCnt,CUBESETCOUNT(_xlpm.cubeSet),_xlpm.dmList,_xlfn.MAP(_xlfn.SEQUENCE(_xlpm.setCnt),_xlfn.LAMBDA(_xlpm.i,CUBERANKEDMEMBER("ThisWorkbookDataModel",_xlpm.cubeSet,_xlpm.i))),_xlpm.fullList,_xlfn._xlws.SORT(_xlfn.UNIQUE(_xlfn._xlws.FILTER(_xlfn.VSTACK(_xlpm.wbList,_xlpm.dmList),_xlfn.VSTACK(_xlpm.wbList,_xlpm.dmList)<>"All"))),_xlpm.idx,ROW()-ROW(tblBudget[[#Headers],[Category]]),IFERROR(INDEX(_xlpm.fullList,_xlpm.idx),""))} | C11: =SUMIFS(tblBudetLog[Budget Amount],tblBudetLog[Category],tblBudget[[#This Row],[Category]],tblBudetLog[Budget Type],"Original Budget",tblBudetLog[Budget Status],"Approved") -> 0 | D11: =SUMIFS(tblBudetLog[Budget Amount],tblBudetLog[Category],tblBudget[[#This Row],[Category]],tblBudetLog[Budget Type],"Budget Adjustment") -> 0 | E11: =tblBudget[[#This Row],[Original Budget]]+tblBudget[[#This Row],[Approved Changes]] -> 0 | F11: =tblBudget[[#This Row],[Revised Budget]]/$B$5 -> 0 | G11: {=SUMPRODUCT((tblForecastLog[Category]=tblBudget[[#This Row],[Category]])*ISNUMBER(MATCH(tblForecastLog[Forecasted Cost Type],{"Actual Cost","Purchase Order","Subcontract","Subcontract CO #1","Subcontract CO #2","Subcontract CO #3","Subcontract CO #4","Subcontract CO #5","Subcontract CO #6","Subcontract CO #7","Subcontract CO #8","Subcontract CO #9","Subcontract CO #10"},0))*(tblForecastLog[Forecasted Cost Status]="Accepted")*tblForecastLog[Forecasted Cost Amount])} -> 0 | H11: {=SUMPRODUCT((tblForecastLog[Category]=tblBudget[[#This Row],[Category]])*ISNUMBER(MATCH(tblForecastLog[Forecasted Cost Type],{"Initial Estimate","Revised Estimate"},0))*ISNUMBER(MATCH(tblForecastLog[Forecasted Cost Status],{"Accepted","Pending"},0))*tblForecastLog[Forecasted Cost Amount])} -> 0 | I11: =tblBudget[[#This Row],[Committed Cost]]+tblBudget[[#This Row],[Estimated Costs]] -> 0 | J11: =tblBudget[[#This Row],[Forecasted Final Cost]]/$B$5 -> 0 | K11: =tblBudget[[#This Row],[Revised Budget]]-tblBudget[[#This Row],[Forecasted Final Cost]] -> 0 | L11: =_xlfn.IFNA(CUBEVALUE("ThisWorkbookDataModel","[Measures].[Amount by _Category]",CUBEMEMBER("ThisWorkbookDataModel","[Fact_JobDetail].[_Category].&["&TRIM($B11)&"]")),0) -> 0
B12: {=_xlfn.LET(_xlpm.trig,RAND()*0,_xlpm.wbRaw,_xlfn.VSTACK(tblForecastLog[Category],tblBudetLog[Category]),_xlpm.wbList,_xlfn._xlws.SORT(_xlfn.UNIQUE(_xlfn._xlws.FILTER(_xlpm.wbRaw,_xlpm.wbRaw<>""))),_xlpm.cubeSet,CUBESET("ThisWorkbookDataModel","[Fact_JobDetail].[_Category].Members"),_xlpm.setCnt,CUBESETCOUNT(_xlpm.cubeSet),_xlpm.dmList,_xlfn.MAP(_xlfn.SEQUENCE(_xlpm.setCnt),_xlfn.LAMBDA(_xlpm.i,CUBERANKEDMEMBER("ThisWorkbookDataModel",_xlpm.cubeSet,_xlpm.i))),_xlpm.fullList,_xlfn._xlws.SORT(_xlfn.UNIQUE(_xlfn._xlws.FILTER(_xlfn.VSTACK(_xlpm.wbList,_xlpm.dmList),_xlfn.VSTACK(_xlpm.wbList,_xlpm.dmList)<>"All"))),_xlpm.idx,ROW()-ROW(tblBudget[[#Headers],[Category]]),IFERROR(INDEX(_xlpm.fullList,_xlpm.idx),""))} | C12: =SUMIFS(tblBudetLog[Budget Amount],tblBudetLog[Category],tblBudget[[#This Row],[Category]],tblBudetLog[Budget Type],"Original Budget",tblBudetLog[Budget Status],"Approved") -> 0 | D12: =SUMIFS(tblBudetLog[Budget Amount],tblBudetLog[Category],tblBudget[[#This Row],[Category]],tblBudetLog[Budget Type],"Budget Adjustment") -> 0 | E12: =tblBudget[[#This Row],[Original Budget]]+tblBudget[[#This Row],[Approved Changes]] -> 0 | F12: =tblBudget[[#This Row],[Revised Budget]]/$B$5 -> 0 | G12: {=SUMPRODUCT((tblForecastLog[Category]=tblBudget[[#This Row],[Category]])*ISNUMBER(MATCH(tblForecastLog[Forecasted Cost Type],{"Actual Cost","Purchase Order","Subcontract","Subcontract CO #1","Subcontract CO #2","Subcontract CO #3","Subcontract CO #4","Subcontract CO #5","Subcontract CO #6","Subcontract CO #7","Subcontract CO #8","Subcontract CO #9","Subcontract CO #10"},0))*(tblForecastLog[Forecasted Cost Status]="Accepted")*tblForecastLog[Forecasted Cost Amount])} -> 0 | H12: {=SUMPRODUCT((tblForecastLog[Category]=tblBudget[[#This Row],[Category]])*ISNUMBER(MATCH(tblForecastLog[Forecasted Cost Type],{"Initial Estimate","Revised Estimate"},0))*ISNUMBER(MATCH(tblForecastLog[Forecasted Cost Status],{"Accepted","Pending"},0))*tblForecastLog[Forecasted Cost Amount])} -> 0 | I12: =tblBudget[[#This Row],[Committed Cost]]+tblBudget[[#This Row],[Estimated Costs]] -> 0 | J12: =tblBudget[[#This Row],[Forecasted Final Cost]]/$B$5 -> 0 | K12: =tblBudget[[#This Row],[Revised Budget]]-tblBudget[[#This Row],[Forecasted Final Cost]] -> 0 | L12: =_xlfn.IFNA(CUBEVALUE("ThisWorkbookDataModel","[Measures].[Amount by _Category]",CUBEMEMBER("ThisWorkbookDataModel","[Fact_JobDetail].[_Category].&["&TRIM($B12)&"]")),0) -> 0
B13: {=_xlfn.LET(_xlpm.trig,RAND()*0,_xlpm.wbRaw,_xlfn.VSTACK(tblForecastLog[Category],tblBudetLog[Category]),_xlpm.wbList,_xlfn._xlws.SORT(_xlfn.UNIQUE(_xlfn._xlws.FILTER(_xlpm.wbRaw,_xlpm.wbRaw<>""))),_xlpm.cubeSet,CUBESET("ThisWorkbookDataModel","[Fact_JobDetail].[_Category].Members"),_xlpm.setCnt,CUBESETCOUNT(_xlpm.cubeSet),_xlpm.dmList,_xlfn.MAP(_xlfn.SEQUENCE(_xlpm.setCnt),_xlfn.LAMBDA(_xlpm.i,CUBERANKEDMEMBER("ThisWorkbookDataModel",_xlpm.cubeSet,_xlpm.i))),_xlpm.fullList,_xlfn._xlws.SORT(_xlfn.UNIQUE(_xlfn._xlws.FILTER(_xlfn.VSTACK(_xlpm.wbList,_xlpm.dmList),_xlfn.VSTACK(_xlpm.wbList,_xlpm.dmList)<>"All"))),_xlpm.idx,ROW()-ROW(tblBudget[[#Headers],[Category]]),IFERROR(INDEX(_xlpm.fullList,_xlpm.idx),""))} | C13: =SUMIFS(tblBudetLog[Budget Amount],tblBudetLog[Category],tblBudget[[#This Row],[Category]],tblBudetLog[Budget Type],"Original Budget",tblBudetLog[Budget Status],"Approved") -> 0 | D13: =SUMIFS(tblBudetLog[Budget Amount],tblBudetLog[Category],tblBudget[[#This Row],[Category]],tblBudetLog[Budget Type],"Budget Adjustment") -> 0 | E13: =tblBudget[[#This Row],[Original Budget]]+tblBudget[[#This Row],[Approved Changes]] -> 0 | F13: =tblBudget[[#This Row],[Revised Budget]]/$B$5 -> 0 | G13: {=SUMPRODUCT((tblForecastLog[Category]=tblBudget[[#This Row],[Category]])*ISNUMBER(MATCH(tblForecastLog[Forecasted Cost Type],{"Actual Cost","Purchase Order","Subcontract","Subcontract CO #1","Subcontract CO #2","Subcontract CO #3","Subcontract CO #4","Subcontract CO #5","Subcontract CO #6","Subcontract CO #7","Subcontract CO #8","Subcontract CO #9","Subcontract CO #10"},0))*(tblForecastLog[Forecasted Cost Status]="Accepted")*tblForecastLog[Forecasted Cost Amount])} -> 0 | H13: {=SUMPRODUCT((tblForecastLog[Category]=tblBudget[[#This Row],[Category]])*ISNUMBER(MATCH(tblForecastLog[Forecasted Cost Type],{"Initial Estimate","Revised Estimate"},0))*ISNUMBER(MATCH(tblForecastLog[Forecasted Cost Status],{"Accepted","Pending"},0))*tblForecastLog[Forecasted Cost Amount])} -> 0 | I13: =tblBudget[[#This Row],[Committed Cost]]+tblBudget[[#This Row],[Estimated Costs]] -> 0 | J13: =tblBudget[[#This Row],[Forecasted Final Cost]]/$B$5 -> 0 | K13: =tblBudget[[#This Row],[Revised Budget]]-tblBudget[[#This Row],[Forecasted Final Cost]] -> 0 | L13: =_xlfn.IFNA(CUBEVALUE("ThisWorkbookDataModel","[Measures].[Amount by _Category]",CUBEMEMBER("ThisWorkbookDataModel","[Fact_JobDetail].[_Category].&["&TRIM($B13)&"]")),0) -> 0
B14: {=_xlfn.LET(_xlpm.trig,RAND()*0,_xlpm.wbRaw,_xlfn.VSTACK(tblForecastLog[Category],tblBudetLog[Category]),_xlpm.wbList,_xlfn._xlws.SORT(_xlfn.UNIQUE(_xlfn._xlws.FILTER(_xlpm.wbRaw,_xlpm.wbRaw<>""))),_xlpm.cubeSet,CUBESET("ThisWorkbookDataModel","[Fact_JobDetail].[_Category].Members"),_xlpm.setCnt,CUBESETCOUNT(_xlpm.cubeSet),_xlpm.dmList,_xlfn.MAP(_xlfn.SEQUENCE(_xlpm.setCnt),_xlfn.LAMBDA(_xlpm.i,CUBERANKEDMEMBER("ThisWorkbookDataModel",_xlpm.cubeSet,_xlpm.i))),_xlpm.fullList,_xlfn._xlws.SORT(_xlfn.UNIQUE(_xlfn._xlws.FILTER(_xlfn.VSTACK(_xlpm.wbList,_xlpm.dmList),_xlfn.VSTACK(_xlpm.wbList,_xlpm.dmList)<>"All"))),_xlpm.idx,ROW()-ROW(tblBudget[[#Headers],[Category]]),IFERROR(INDEX(_xlpm.fullList,_xlpm.idx),""))} | C14: =SUMIFS(tblBudetLog[Budget Amount],tblBudetLog[Category],tblBudget[[#This Row],[Category]],tblBudetLog[Budget Type],"Original Budget",tblBudetLog[Budget Status],"Approved") -> 0 | D14: =SUMIFS(tblBudetLog[Budget Amount],tblBudetLog[Category],tblBudget[[#This Row],[Category]],tblBudetLog[Budget Type],"Budget Adjustment") -> 0 | E14: =tblBudget[[#This Row],[Original Budget]]+tblBudget[[#This Row],[Approved Changes]] -> 0 | F14: =tblBudget[[#This Row],[Revised Budget]]/$B$5 -> 0 | G14: {=SUMPRODUCT((tblForecastLog[Category]=tblBudget[[#This Row],[Category]])*ISNUMBER(MATCH(tblForecastLog[Forecasted Cost Type],{"Actual Cost","Purchase Order","Subcontract","Subcontract CO #1","Subcontract CO #2","Subcontract CO #3","Subcontract CO #4","Subcontract CO #5","Subcontract CO #6","Subcontract CO #7","Subcontract CO #8","Subcontract CO #9","Subcontract CO #10"},0))*(tblForecastLog[Forecasted Cost Status]="Accepted")*tblForecastLog[Forecasted Cost Amount])} -> 0 | H14: {=SUMPRODUCT((tblForecastLog[Category]=tblBudget[[#This Row],[Category]])*ISNUMBER(MATCH(tblForecastLog[Forecasted Cost Type],{"Initial Estimate","Revised Estimate"},0))*ISNUMBER(MATCH(tblForecastLog[Forecasted Cost Status],{"Accepted","Pending"},0))*tblForecastLog[Forecasted Cost Amount])} -> 0 | I14: =tblBudget[[#This Row],[Committed Cost]]+tblBudget[[#This Row],[Estimated Costs]] -> 0 | J14: =tblBudget[[#This Row],[Forecasted Final Cost]]/$B$5 -> 0 | K14: =tblBudget[[#This Row],[Revised Budget]]-tblBudget[[#This Row],[Forecasted Final Cost]] -> 0 | L14: =_xlfn.IFNA(CUBEVALUE("ThisWorkbookDataModel","[Measures].[Amount by _Category]",CUBEMEMBER("ThisWorkbookDataModel","[Fact_JobDetail].[_Category].&["&TRIM($B14)&"]")),0) -> 0
B15: {=_xlfn.LET(_xlpm.trig,RAND()*0,_xlpm.wbRaw,_xlfn.VSTACK(tblForecastLog[Category],tblBudetLog[Category]),_xlpm.wbList,_xlfn._xlws.SORT(_xlfn.UNIQUE(_xlfn._xlws.FILTER(_xlpm.wbRaw,_xlpm.wbRaw<>""))),_xlpm.cubeSet,CUBESET("ThisWorkbookDataModel","[Fact_JobDetail].[_Category].Members"),_xlpm.setCnt,CUBESETCOUNT(_xlpm.cubeSet),_xlpm.dmList,_xlfn.MAP(_xlfn.SEQUENCE(_xlpm.setCnt),_xlfn.LAMBDA(_xlpm.i,CUBERANKEDMEMBER("ThisWorkbookDataModel",_xlpm.cubeSet,_xlpm.i))),_xlpm.fullList,_xlfn._xlws.SORT(_xlfn.UNIQUE(_xlfn._xlws.FILTER(_xlfn.VSTACK(_xlpm.wbList,_xlpm.dmList),_xlfn.VSTACK(_xlpm.wbList,_xlpm.dmList)<>"All"))),_xlpm.idx,ROW()-ROW(tblBudget[[#Headers],[Category]]),IFERROR(INDEX(_xlpm.fullList,_xlpm.idx),""))} | C15: =SUMIFS(tblBudetLog[Budget Amount],tblBudetLog[Category],tblBudget[[#This Row],[Category]],tblBudetLog[Budget Type],"Original Budget",tblBudetLog[Budget Status],"Approved") -> 0 | D15: =SUMIFS(tblBudetLog[Budget Amount],tblBudetLog[Category],tblBudget[[#This Row],[Category]],tblBudetLog[Budget Type],"Budget Adjustment") -> 0 | E15: =tblBudget[[#This Row],[Original Budget]]+tblBudget[[#This Row],[Approved Changes]] -> 0 | F15: =tblBudget[[#This Row],[Revised Budget]]/$B$5 -> 0 | G15: {=SUMPRODUCT((tblForecastLog[Category]=tblBudget[[#This Row],[Category]])*ISNUMBER(MATCH(tblForecastLog[Forecasted Cost Type],{"Actual Cost","Purchase Order","Subcontract","Subcontract CO #1","Subcontract CO #2","Subcontract CO #3","Subcontract CO #4","Subcontract CO #5","Subcontract CO #6","Subcontract CO #7","Subcontract CO #8","Subcontract CO #9","Subcontract CO #10"},0))*(tblForecastLog[Forecasted Cost Status]="Accepted")*tblForecastLog[Forecasted Cost Amount])} -> 0 | H15: {=SUMPRODUCT((tblForecastLog[Category]=tblBudget[[#This Row],[Category]])*ISNUMBER(MATCH(tblForecastLog[Forecasted Cost Type],{"Initial Estimate","Revised Estimate"},0))*ISNUMBER(MATCH(tblForecastLog[Forecasted Cost Status],{"Accepted","Pending"},0))*tblForecastLog[Forecasted Cost Amount])} -> 0 | I15: =tblBudget[[#This Row],[Committed Cost]]+tblBudget[[#This Row],[Estimated Costs]] -> 0 | J15: =tblBudget[[#This Row],[Forecasted Final Cost]]/$B$5 -> 0 | K15: =tblBudget[[#This Row],[Revised Budget]]-tblBudget[[#This Row],[Forecasted Final Cost]] -> 0 | L15: =_xlfn.IFNA(CUBEVALUE("ThisWorkbookDataModel","[Measures].[Amount by _Category]",CUBEMEMBER("ThisWorkbookDataModel","[Fact_JobDetail].[_Category].&["&TRIM($B15)&"]")),0) -> 0
B16: {=_xlfn.LET(_xlpm.trig,RAND()*0,_xlpm.wbRaw,_xlfn.VSTACK(tblForecastLog[Category],tblBudetLog[Category]),_xlpm.wbList,_xlfn._xlws.SORT(_xlfn.UNIQUE(_xlfn._xlws.FILTER(_xlpm.wbRaw,_xlpm.wbRaw<>""))),_xlpm.cubeSet,CUBESET("ThisWorkbookDataModel","[Fact_JobDetail].[_Category].Members"),_xlpm.setCnt,CUBESETCOUNT(_xlpm.cubeSet),_xlpm.dmList,_xlfn.MAP(_xlfn.SEQUENCE(_xlpm.setCnt),_xlfn.LAMBDA(_xlpm.i,CUBERANKEDMEMBER("ThisWorkbookDataModel",_xlpm.cubeSet,_xlpm.i))),_xlpm.fullList,_xlfn._xlws.SORT(_xlfn.UNIQUE(_xlfn._xlws.FILTER(_xlfn.VSTACK(_xlpm.wbList,_xlpm.dmList),_xlfn.VSTACK(_xlpm.wbList,_xlpm.dmList)<>"All"))),_xlpm.idx,ROW()-ROW(tblBudget[[#Headers],[Category]]),IFERROR(INDEX(_xlpm.fullList,_xlpm.idx),""))} | C16: =SUMIFS(tblBudetLog[Budget Amount],tblBudetLog[Category],tblBudget[[#This Row],[Category]],tblBudetLog[Budget Type],"Original Budget",tblBudetLog[Budget Status],"Approved") -> 0 | D16: =SUMIFS(tblBudetLog[Budget Amount],tblBudetLog[Category],tblBudget[[#This Row],[Category]],tblBudetLog[Budget Type],"Budget Adjustment") -> 0 | E16: =tblBudget[[#This Row],[Original Budget]]+tblBudget[[#This Row],[Approved Changes]] -> 0 | F16: =tblBudget[[#This Row],[Revised Budget]]/$B$5 -> 0 | G16: {=SUMPRODUCT((tblForecastLog[Category]=tblBudget[[#This Row],[Category]])*ISNUMBER(MATCH(tblForecastLog[Forecasted Cost Type],{"Actual Cost","Purchase Order","Subcontract","Subcontract CO #1","Subcontract CO #2","Subcontract CO #3","Subcontract CO #4","Subcontract CO #5","Subcontract CO #6","Subcontract CO #7","Subcontract CO #8","Subcontract CO #9","Subcontract CO #10"},0))*(tblForecastLog[Forecasted Cost Status]="Accepted")*tblForecastLog[Forecasted Cost Amount])} -> 0 | H16: {=SUMPRODUCT((tblForecastLog[Category]=tblBudget[[#This Row],[Category]])*ISNUMBER(MATCH(tblForecastLog[Forecasted Cost Type],{"Initial Estimate","Revised Estimate"},0))*ISNUMBER(MATCH(tblForecastLog[Forecasted Cost Status],{"Accepted","Pending"},0))*tblForecastLog[Forecasted Cost Amount])} -> 0 | I16: =tblBudget[[#This Row],[Committed Cost]]+tblBudget[[#This Row],[Estimated Costs]] -> 0 | J16: =tblBudget[[#This Row],[Forecasted Final Cost]]/$B$5 -> 0 | K16: =tblBudget[[#This Row],[Revised Budget]]-tblBudget[[#This Row],[Forecasted Final Cost]] -> 0 | L16: =_xlfn.IFNA(CUBEVALUE("ThisWorkbookDataModel","[Measures].[Amount by _Category]",CUBEMEMBER("ThisWorkbookDataModel","[Fact_JobDetail].[_Category].&["&TRIM($B16)&"]")),0) -> 0
B17: {=_xlfn.LET(_xlpm.trig,RAND()*0,_xlpm.wbRaw,_xlfn.VSTACK(tblForecastLog[Category],tblBudetLog[Category]),_xlpm.wbList,_xlfn._xlws.SORT(_xlfn.UNIQUE(_xlfn._xlws.FILTER(_xlpm.wbRaw,_xlpm.wbRaw<>""))),_xlpm.cubeSet,CUBESET("ThisWorkbookDataModel","[Fact_JobDetail].[_Category].Members"),_xlpm.setCnt,CUBESETCOUNT(_xlpm.cubeSet),_xlpm.dmList,_xlfn.MAP(_xlfn.SEQUENCE(_xlpm.setCnt),_xlfn.LAMBDA(_xlpm.i,CUBERANKEDMEMBER("ThisWorkbookDataModel",_xlpm.cubeSet,_xlpm.i))),_xlpm.fullList,_xlfn._xlws.SORT(_xlfn.UNIQUE(_xlfn._xlws.FILTER(_xlfn.VSTACK(_xlpm.wbList,_xlpm.dmList),_xlfn.VSTACK(_xlpm.wbList,_xlpm.dmList)<>"All"))),_xlpm.idx,ROW()-ROW(tblBudget[[#Headers],[Category]]),IFERROR(INDEX(_xlpm.fullList,_xlpm.idx),""))} | C17: =SUMIFS(tblBudetLog[Budget Amount],tblBudetLog[Category],tblBudget[[#This Row],[Category]],tblBudetLog[Budget Type],"Original Budget",tblBudetLog[Budget Status],"Approved") -> 0 | D17: =SUMIFS(tblBudetLog[Budget Amount],tblBudetLog[Category],tblBudget[[#This Row],[Category]],tblBudetLog[Budget Type],"Budget Adjustment") -> 0 | E17: =tblBudget[[#This Row],[Original Budget]]+tblBudget[[#This Row],[Approved Changes]] -> 0 | F17: =tblBudget[[#This Row],[Revised Budget]]/$B$5 -> 0 | G17: {=SUMPRODUCT((tblForecastLog[Category]=tblBudget[[#This Row],[Category]])*ISNUMBER(MATCH(tblForecastLog[Forecasted Cost Type],{"Actual Cost","Purchase Order","Subcontract","Subcontract CO #1","Subcontract CO #2","Subcontract CO #3","Subcontract CO #4","Subcontract CO #5","Subcontract CO #6","Subcontract CO #7","Subcontract CO #8","Subcontract CO #9","Subcontract CO #10"},0))*(tblForecastLog[Forecasted Cost Status]="Accepted")*tblForecastLog[Forecasted Cost Amount])} -> 0 | H17: {=SUMPRODUCT((tblForecastLog[Category]=tblBudget[[#This Row],[Category]])*ISNUMBER(MATCH(tblForecastLog[Forecasted Cost Type],{"Initial Estimate","Revised Estimate"},0))*ISNUMBER(MATCH(tblForecastLog[Forecasted Cost Status],{"Accepted","Pending"},0))*tblForecastLog[Forecasted Cost Amount])} -> 0 | I17: =tblBudget[[#This Row],[Committed Cost]]+tblBudget[[#This Row],[Estimated Costs]] -> 0 | J17: =tblBudget[[#This Row],[Forecasted Final Cost]]/$B$5 -> 0 | K17: =tblBudget[[#This Row],[Revised Budget]]-tblBudget[[#This Row],[Forecasted Final Cost]] -> 0 | L17: =_xlfn.IFNA(CUBEVALUE("ThisWorkbookDataModel","[Measures].[Amount by _Category]",CUBEMEMBER("ThisWorkbookDataModel","[Fact_JobDetail].[_Category].&["&TRIM($B17)&"]")),0) -> 0
B18: {=_xlfn.LET(_xlpm.trig,RAND()*0,_xlpm.wbRaw,_xlfn.VSTACK(tblForecastLog[Category],tblBudetLog[Category]),_xlpm.wbList,_xlfn._xlws.SORT(_xlfn.UNIQUE(_xlfn._xlws.FILTER(_xlpm.wbRaw,_xlpm.wbRaw<>""))),_xlpm.cubeSet,CUBESET("ThisWorkbookDataModel","[Fact_JobDetail].[_Category].Members"),_xlpm.setCnt,CUBESETCOUNT(_xlpm.cubeSet),_xlpm.dmList,_xlfn.MAP(_xlfn.SEQUENCE(_xlpm.setCnt),_xlfn.LAMBDA(_xlpm.i,CUBERANKEDMEMBER("ThisWorkbookDataModel",_xlpm.cubeSet,_xlpm.i))),_xlpm.fullList,_xlfn._xlws.SORT(_xlfn.UNIQUE(_xlfn._xlws.FILTER(_xlfn.VSTACK(_xlpm.wbList,_xlpm.dmList),_xlfn.VSTACK(_xlpm.wbList,_xlpm.dmList)<>"All"))),_xlpm.idx,ROW()-ROW(tblBudget[[#Headers],[Category]]),IFERROR(INDEX(_xlpm.fullList,_xlpm.idx),""))} | C18: =SUMIFS(tblBudetLog[Budget Amount],tblBudetLog[Category],tblBudget[[#This Row],[Category]],tblBudetLog[Budget Type],"Original Budget",tblBudetLog[Budget Status],"Approved") -> 0 | D18: =SUMIFS(tblBudetLog[Budget Amount],tblBudetLog[Category],tblBudget[[#This Row],[Category]],tblBudetLog[Budget Type],"Budget Adjustment") -> 0 | E18: =tblBudget[[#This Row],[Original Budget]]+tblBudget[[#This Row],[Approved Changes]] -> 0 | F18: =tblBudget[[#This Row],[Revised Budget]]/$B$5 -> 0 | G18: {=SUMPRODUCT((tblForecastLog[Category]=tblBudget[[#This Row],[Category]])*ISNUMBER(MATCH(tblForecastLog[Forecasted Cost Type],{"Actual Cost","Purchase Order","Subcontract","Subcontract CO #1","Subcontract CO #2","Subcontract CO #3","Subcontract CO #4","Subcontract CO #5","Subcontract CO #6","Subcontract CO #7","Subcontract CO #8","Subcontract CO #9","Subcontract CO #10"},0))*(tblForecastLog[Forecasted Cost Status]="Accepted")*tblForecastLog[Forecasted Cost Amount])} -> 0 | H18: {=SUMPRODUCT((tblForecastLog[Category]=tblBudget[[#This Row],[Category]])*ISNUMBER(MATCH(tblForecastLog[Forecasted Cost Type],{"Initial Estimate","Revised Estimate"},0))*ISNUMBER(MATCH(tblForecastLog[Forecasted Cost Status],{"Accepted","Pending"},0))*tblForecastLog[Forecasted Cost Amount])} -> 0 | I18: =tblBudget[[#This Row],[Committed Cost]]+tblBudget[[#This Row],[Estimated Costs]] -> 0 | J18: =tblBudget[[#This Row],[Forecasted Final Cost]]/$B$5 -> 0 | K18: =tblBudget[[#This Row],[Revised Budget]]-tblBudget[[#This Row],[Forecasted Final Cost]] -> 0 | L18: =_xlfn.IFNA(CUBEVALUE("ThisWorkbookDataModel","[Measures].[Amount by _Category]",CUBEMEMBER("ThisWorkbookDataModel","[Fact_JobDetail].[_Category].&["&TRIM($B18)&"]")),0) -> 0
B19: {=_xlfn.LET(_xlpm.trig,RAND()*0,_xlpm.wbRaw,_xlfn.VSTACK(tblForecastLog[Category],tblBudetLog[Category]),_xlpm.wbList,_xlfn._xlws.SORT(_xlfn.UNIQUE(_xlfn._xlws.FILTER(_xlpm.wbRaw,_xlpm.wbRaw<>""))),_xlpm.cubeSet,CUBESET("ThisWorkbookDataModel","[Fact_JobDetail].[_Category].Members"),_xlpm.setCnt,CUBESETCOUNT(_xlpm.cubeSet),_xlpm.dmList,_xlfn.MAP(_xlfn.SEQUENCE(_xlpm.setCnt),_xlfn.LAMBDA(_xlpm.i,CUBERANKEDMEMBER("ThisWorkbookDataModel",_xlpm.cubeSet,_xlpm.i))),_xlpm.fullList,_xlfn._xlws.SORT(_xlfn.UNIQUE(_xlfn._xlws.FILTER(_xlfn.VSTACK(_xlpm.wbList,_xlpm.dmList),_xlfn.VSTACK(_xlpm.wbList,_xlpm.dmList)<>"All"))),_xlpm.idx,ROW()-ROW(tblBudget[[#Headers],[Category]]),IFERROR(INDEX(_xlpm.fullList,_xlpm.idx),""))} | C19: =SUMIFS(tblBudetLog[Budget Amount],tblBudetLog[Category],tblBudget[[#This Row],[Category]],tblBudetLog[Budget Type],"Original Budget",tblBudetLog[Budget Status],"Approved") -> 0 | D19: =SUMIFS(tblBudetLog[Budget Amount],tblBudetLog[Category],tblBudget[[#This Row],[Category]],tblBudetLog[Budget Type],"Budget Adjustment") -> 0 | E19: =tblBudget[[#This Row],[Original Budget]]+tblBudget[[#This Row],[Approved Changes]] -> 0 | F19: =tblBudget[[#This Row],[Revised Budget]]/$B$5 -> 0 | G19: {=SUMPRODUCT((tblForecastLog[Category]=tblBudget[[#This Row],[Category]])*ISNUMBER(MATCH(tblForecastLog[Forecasted Cost Type],{"Actual Cost","Purchase Order","Subcontract","Subcontract CO #1","Subcontract CO #2","Subcontract CO #3","Subcontract CO #4","Subcontract CO #5","Subcontract CO #6","Subcontract CO #7","Subcontract CO #8","Subcontract CO #9","Subcontract CO #10"},0))*(tblForecastLog[Forecasted Cost Status]="Accepted")*tblForecastLog[Forecasted Cost Amount])} -> 0 | H19: {=SUMPRODUCT((tblForecastLog[Category]=tblBudget[[#This Row],[Category]])*ISNUMBER(MATCH(tblForecastLog[Forecasted Cost Type],{"Initial Estimate","Revised Estimate"},0))*ISNUMBER(MATCH(tblForecastLog[Forecasted Cost Status],{"Accepted","Pending"},0))*tblForecastLog[Forecasted Cost Amount])} -> 0 | I19: =tblBudget[[#This Row],[Committed Cost]]+tblBudget[[#This Row],[Estimated Costs]] -> 0 | J19: =tblBudget[[#This Row],[Forecasted Final Cost]]/$B$5 -> 0 | K19: =tblBudget[[#This Row],[Revised Budget]]-tblBudget[[#This Row],[Forecasted Final Cost]] -> 0 | L19: =_xlfn.IFNA(CUBEVALUE("ThisWorkbookDataModel","[Measures].[Amount by _Category]",CUBEMEMBER("ThisWorkbookDataModel","[Fact_JobDetail].[_Category].&["&TRIM($B19)&"]")),0) -> 0
... B63: {=_xlfn.LET(_xlpm.trig,RAND()*0,_xlpm.wbRaw,_xlfn.VSTACK(tblForecastLog[Category],tblBudetLog[Category]),_xlpm.wbList,_xlfn._xlws.SORT(_xlfn.UNIQUE(_xlfn._xlws.FILTER(_xlpm.wbRaw,_xlpm.wbRaw<>""))),_xlpm.cubeSet,CUBESET("ThisWorkbookDataModel","[Fact_JobDetail].[_Category].Members"),_xlpm.setCnt,CUBESETCOUNT(_xlpm.cubeSet),_xlpm.dmList,_xlfn.MAP(_xlfn.SEQUENCE(_xlpm.setCnt),_xlfn.LAMBDA(_xlpm.i,CUBERANKEDMEMBER("ThisWorkbookDataModel",_xlpm.cubeSet,_xlpm.i))),_xlpm.fullList,_xlfn._xlws.SORT(_xlfn.UNIQUE(_xlfn._xlws.FILTER(_xlfn.VSTACK(_xlpm.wbList,_xlpm.dmList),_xlfn.VSTACK(_xlpm.wbList,_xlpm.dmList)<>"All"))),_xlpm.idx,ROW()-ROW(tblBudget[[#Headers],[Category]]),IFERROR(INDEX(_xlpm.fullList,_xlpm.idx),""))} | C63: =SUMIFS(tblBudetLog[Budget Amount],tblBudetLog[Category],tblBudget[[#This Row],[Category]],tblBudetLog[Budget Type],"Original Budget",tblBudetLog[Budget Status],"Approved") -> 0 | D63: =SUMIFS(tblBudetLog[Budget Amount],tblBudetLog[Category],tblBudget[[#This Row],[Category]],tblBudetLog[Budget Type],"Budget Adjustment") -> 0 | E63: =tblBudget[[#This Row],[Original Budget]]+tblBudget[[#This Row],[Approved Changes]] -> 0 | F63: =tblBudget[[#This Row],[Revised Budget]]/$B$5 -> 0 | G63: {=SUMPRODUCT((tblForecastLog[Category]=tblBudget[[#This Row],[Category]])*ISNUMBER(MATCH(tblForecastLog[Forecasted Cost Type],{"Actual Cost","Purchase Order","Subcontract","Subcontract CO #1","Subcontract CO #2","Subcontract CO #3","Subcontract CO #4","Subcontract CO #5","Subcontract CO #6","Subcontract CO #7","Subcontract CO #8","Subcontract CO #9","Subcontract CO #10"},0))*(tblForecastLog[Forecasted Cost Status]="Accepted")*tblForecastLog[Forecasted Cost Amount])} -> 0 | H63: {=SUMPRODUCT((tblForecastLog[Category]=tblBudget[[#This Row],[Category]])*ISNUMBER(MATCH(tblForecastLog[Forecasted Cost Type],{"Initial Estimate","Revised Estimate"},0))*ISNUMBER(MATCH(tblForecastLog[Forecasted Cost Status],{"Accepted","Pending"},0))*tblForecastLog[Forecasted Cost Amount])} -> 0 | I63: =tblBudget[[#This Row],[Committed Cost]]+tblBudget[[#This Row],[Estimated Costs]] -> 0 | J63: =tblBudget[[#This Row],[Forecasted Final Cost]]/$B$5 -> 0 | K63: =tblBudget[[#This Row],[Revised Budget]]-tblBudget[[#This Row],[Forecasted Final Cost]] -> 0 | L63: =_xlfn.IFNA(CUBEVALUE("ThisWorkbookDataModel","[Measures].[Amount by _Category]",CUBEMEMBER("ThisWorkbookDataModel","[Fact_JobDetail].[_Category].&["&TRIM($B63)&"]")),0) -> 0
C64: =SUBTOTAL(109,tblBudget[Original Budget]) -> 0 | D64: =SUBTOTAL(109,tblBudget[Approved Changes]) -> 0 | E64: =SUBTOTAL(109,tblBudget[Revised Budget]) -> 0 | F64: =SUBTOTAL(109,tblBudget[Revised Budget PSF]) -> 0 | G64: =SUBTOTAL(109,tblBudget[Committed Cost]) -> 0 | H64: =SUBTOTAL(109,tblBudget[Estimated Costs]) -> 0 | I64: =SUBTOTAL(109,tblBudget[Forecasted Final Cost]) -> 0 | J64: =SUBTOTAL(109,tblBudget[Forecasted Cost PSF]) -> 0 | K64: =SUBTOTAL(109,tblBudget[Forecasted (Over)/Under]) -> 0 | L64: =SUBTOTAL(109,tblBudget[Invoiced to Date]) -> 0

Sheet zz_data
B1: PropertyCode | C1: PropertyName | E1: ProjectManager | G1: VendorCode | H1: VendorName | J1: Category | K1: CostCode | L1: Description | N1: JobType | O1: JobStatus | P1: DevFeeType | Q1: ForecastType | R1: ForecastStatus | S1: BudgetType | T1: BudgetStatus | V1: Vendors_Dynamic
